# 代码生成时间: 2025-08-03 04:28:13
import os
from celery import Celery
from celery.exceptions import SoftTimeLimitExceeded
from datetime import datetime

# 配置Celery
app = Celery('data_backup_restore', broker='pyamqp://guest@localhost//')

# 定义备份任务
@app.task(bind=True, soft_time_limit=60)
def backup_data(self, data_path):
    '''
    备份数据到指定路径
    :param self: Celery task实例
    :param data_path: 数据文件路径
    '''
    try:
        # 假设备份操作
        backup_path = f"{data_path}_backup_{datetime.now().strftime('%Y%m%d%H%M%S')}.dat"
        with open(data_path, 'rb') as f_in, open(backup_path, 'wb') as f_out:
            f_out.write(f_in.read())
        return f"Backup successful: {backup_path}"
    except Exception as e:
        raise self.retry(exc=e)

# 定义恢复任务
@app.task(bind=True, soft_time_limit=60)
def restore_data(self, backup_path, original_path):
    '''
    从备份文件恢复数据到原始路径
    :param self: Celery task实例
    :param backup_path: 备份文件路径
    :param original_path: 原始文件路径
    '''
    try:
        # 假设恢复操作
        with open(backup_path, 'rb') as f_in, open(original_path, 'wb') as f_out:
            f_out.write(f_in.read())
        return f"Restore successful: {original_path}"
    except Exception as e:
        raise self.retry(exc=e)

if __name__ == '__main__':
    # 启动Celery worker
    app.start()