# 代码生成时间: 2025-09-01 10:52:28
# random_number_generator.py

"""
# 增强安全性
This module provides a Celery task for generating random numbers.
It demonstrates the use of Celery in a Python application to perform asynchronous
tasks such as generating random numbers and handling errors gracefully.
"""

from celery import Celery
from celery.utils.log import get_task_logger
import random
import sys

# Configure the Celery app
app = Celery('random_number_generator', broker='pyamqp://guest@localhost//')
app.conf.update(
    task_serializer='json',
    accept_content=['json'],
    result_serializer='json',
    timezone='UTC',
    enable_utc=True,
)

# Get a logger instance
logger = get_task_logger(__name__)
# TODO: 优化性能


@app.task(name='generate_random_number', bind=True)
def generate_random_number(self, min_value=0, max_value=100, attempts=1):
    """
    Asynchronously generate a random number between min_value and max_value.
# 扩展功能模块
    If the number is generated successfully, return the result.
    If the number is not generated within attempts, raise an exception.
# 添加错误处理
    
    :param self: Celery task instance
    :param min_value: The minimum value of the random number (inclusive)
# 改进用户体验
    :param max_value: The maximum value of the random number (exclusive)
    :param attempts: The number of attempts to generate the random number
    :return: The generated random number
    :raises: ValueError if the number is not generated within attempts
    """
    for _ in range(attempts):
# FIXME: 处理边界情况
        try:
# 优化算法效率
            random_number = random.randint(min_value, max_value)
# 优化算法效率
            logger.info(f'Generated random number: {random_number}')
            return random_number
        except Exception as e:
            logger.error(f'Error generating random number: {e}')
            raise ValueError(f'Failed to generate random number after {attempts} attempts')
